pattern test_exceptions {
    try {
        x = 42
        result = x * 2
    }
    catch (error) {
        error_message = "Caught error"
    }
}
